{
    "name": "The Great Egg",
    "icon": "minecraft:egg",
    "category": "multiblocks",
    "pages": [
		{
            "type": "text",
            "text": "A symbol of life, a subject of many arguments, and somewhat of a nutritional powerhouse and a superfood: the Egg is, without a doubt, one of the most important things in everyday life. Trying to do things without the involvement of an Egg would be pointless and, in all honesty, really stupid, but getting some would almost certainly bring in good luck and prosperity."
        },
		{
			"type":	"text",
			"text": "After the motion is set, you, while being eager to get some eggs, might think of scouting out for Chickens, or using bait to lure them into a trap, like a seasoned hunter would, or just letting nature take its course and bless you with a flock of wild specimen...$(br)Ultimately, all of those options would just tire you out and end up being a massive waste of time. Things like these need a different approach, free of narrow-minded cultural assumptions."
		},
		{
			"type":	"text",
			"text": "An egg cannot be obtained without a chicken, yet a chicken cannot be obtained without an egg, either.$(br)Since we already know that chickens are out of the question, there is just one option left: using The Great Egg to will ''lesser'' Eggs into existence. Necessities:$(br)$(li)A mere 288 Limestone blocks,$(li)Handful of Thatch,$(li)One Small Item Input Bus,$(li)One Small Item Output Bus,$(li)One Tiny Fluid Input Hatch,$(li)A Machine Controller."
		},
        {
            "type": "multiblock",
            "name":"The Great Egg",
			"text":"The ''proverbial'' Egg. Takes a whole 5 minutes to procure an egg in exchange for 100ml of Seed Oil and 1 Seed.",
			"multiblock": {
				"mapping":{
					"0":"modularmachinery:blockcontroller[facing=north]",
					"T":"quark:thatch",
					"b":"modularmachinery:blockinputbus[size=small]",
					"B":"modularmachinery:blockoutputbus[size=small]",
					"h":"modularmachinery:blockfluidinputhatch[size=tiny]",
					"L":"quark:limestone[variant=stone_limestone]"
				},
				"pattern":[
					["____________",
					"____________",
					"____________",
					"____________",
					"_____LL_____",
					"____LLLL____",
					"____LLLL____",
					"_____LL_____",
					"____________",
					"____________",
					"____________",
					"____________"
					],
					["____________",
					"____________",
					"____________",
					"____LLLL____",
					"___LL__LL___",
					"___L____L___",
					"___L____L___",
					"___LL__LL___",
					"____LLLL____",
					"____________",
					"____________",
					"____________"
					],
					["____________",
					"____________",
					"____LLLL____",
					"___L____L___",
					"__L______L__",
					"__L______L__",
					"__L______L__",
					"__L______L__",
					"___L____L___",
					"____LLLL____",
					"____________",
					"____________"
					],
					["____________",
					"____________",
					"____LLLL____",
					"___L____L___",
					"__L______L__",
					"__L______L__",
					"__L______L__",
					"__L______L__",
					"___L____L___",
					"____LLLL____",
					"____________",
					"____________"
					],
					["____________",
					"____LLLL____",
					"___L____L___",
					"__L______L__",
					"_L________L_",
					"_L________L_",
					"_L________L_",
					"_L________L_",
					"__L______L__",
					"___L____L___",
					"____LLLL____",
					"____________"
					],
					["____________",
					"____LLLL____",
					"___L____L___",
					"__L______L__",
					"_L________L_",
					"_L________L_",
					"_L________L_",
					"_L________L_",
					"__L______L__",
					"___L____L___",
					"____LLLL____",
					"____________"
					],
					["____LLLL____",
					"___L____L___",
					"__L______L__",
					"_L________L_",
					"L__________L",
					"L__________L",
					"L__________L",
					"L__________L",
					"_L________L_",
					"__L______L__",
					"___L____L___",
					"____LLLL____"
					],
					["____LLLL____",
					"___L____L___",
					"__L______L__",
					"_L________L_",
					"L__________L",
					"L__________L",
					"L__________L",
					"L__________L",
					"_L________L_",
					"__L______L__",
					"___L____L___",
					"____LLLL____"
					],
					["____LLLL____",
					"___L____L___",
					"__L______L__",
					"_L________L_",
					"L__________L",
					"L__________L",
					"L__________L",
					"L__________L",
					"_L________L_",
					"__L______L__",
					"___L____L___",
					"____LLLL____"
					],
					["____________",
					"____L__L____",
					"___L____L___",
					"__L______L__",
					"_L________L_",
					"____________",
					"____________",
					"_L________L_",
					"__L______L__",
					"___L____L___",
					"____L__L____",
					"____________"
					],
					["____________",
					"____L__L____",
					"___L____L___",
					"__L______L__",
					"_L________L_",
					"____________",
					"____________",
					"_L________L_",
					"__L______L__",
					"___L____L___",
					"____L__L____",
					"____________"
					],
					["____________",
					"____________",
					"____LLLL____",
					"___LLLLLL___",
					"__LL____LL__",
					"__LL____LL__",
					"__LL____LL__",
					"__LL____LL__",
					"___LLLLLL___",
					"____LLLL____",
					"____________",
					"____________"
					],
					["____________",
					"____________",
					"____________",
					"____TTTT____",
					"___BLLLLT___",
					"___TLLLLT___",
					"___0LLLLT___",
					"___bLLLLT___",
					"____hTTT____",
					"____________",
					"____________",
					"____________"
					],
					["____________",
					"____________",
					"____________",
					"____________",
					"____TTTT____",
					"____TTTT____",
					"____TTTT____",
					"____TTTT____",
					"____________",
					"____________",
					"____________",
					"____________"
					]
				],
				"symmetrical":true
			}
        },
		{
            "type": "text",
            "text": "As most things autonomously aim towards improvement, The Slow And Somewhat Inefficient, But Great Nonetheless Egg could use some, too.$(br)The problem is, it's an Egg. Or, at the very least, it appears to be, and any attempt to ask it directly would more than likely fail because it's doesn't appear to be sentient.$(br2)Anyway, replacing $(o)all/$ of the Limestone blocks with $(l)Diorite/$ is bound to make The Egg just this much Greater."
        },
		{
            "type": "multiblock",
            "name":"The Greater Egg",
			"text":"The Greater Egg can present an additional egg (sometimes) every 2,5 minutes, while asking for just 80ml of Seed Oil!",
			"multiblock": {
				"mapping":{
					"0":"modularmachinery:blockcontroller[facing=north]",
					"T":"quark:thatch",
					"b":"modularmachinery:blockinputbus[size=small]",
					"B":"modularmachinery:blockoutputbus[size=small]",
					"h":"modularmachinery:blockfluidinputhatch[size=tiny]",
					"L":"minecraft:stone[variant=diorite]"
				},
				"pattern":[
					["____________",
					"____________",
					"____________",
					"____________",
					"_____LL_____",
					"____LLLL____",
					"____LLLL____",
					"_____LL_____",
					"____________",
					"____________",
					"____________",
					"____________"
					],
					["____________",
					"____________",
					"____________",
					"____LLLL____",
					"___LL__LL___",
					"___L____L___",
					"___L____L___",
					"___LL__LL___",
					"____LLLL____",
					"____________",
					"____________",
					"____________"
					],
					["____________",
					"____________",
					"____LLLL____",
					"___L____L___",
					"__L______L__",
					"__L______L__",
					"__L______L__",
					"__L______L__",
					"___L____L___",
					"____LLLL____",
					"____________",
					"____________"
					],
					["____________",
					"____________",
					"____LLLL____",
					"___L____L___",
					"__L______L__",
					"__L______L__",
					"__L______L__",
					"__L______L__",
					"___L____L___",
					"____LLLL____",
					"____________",
					"____________"
					],
					["____________",
					"____LLLL____",
					"___L____L___",
					"__L______L__",
					"_L________L_",
					"_L________L_",
					"_L________L_",
					"_L________L_",
					"__L______L__",
					"___L____L___",
					"____LLLL____",
					"____________"
					],
					["____________",
					"____LLLL____",
					"___L____L___",
					"__L______L__",
					"_L________L_",
					"_L________L_",
					"_L________L_",
					"_L________L_",
					"__L______L__",
					"___L____L___",
					"____LLLL____",
					"____________"
					],
					["____LLLL____",
					"___L____L___",
					"__L______L__",
					"_L________L_",
					"L__________L",
					"L__________L",
					"L__________L",
					"L__________L",
					"_L________L_",
					"__L______L__",
					"___L____L___",
					"____LLLL____"
					],
					["____LLLL____",
					"___L____L___",
					"__L______L__",
					"_L________L_",
					"L__________L",
					"L__________L",
					"L__________L",
					"L__________L",
					"_L________L_",
					"__L______L__",
					"___L____L___",
					"____LLLL____"
					],
					["____LLLL____",
					"___L____L___",
					"__L______L__",
					"_L________L_",
					"L__________L",
					"L__________L",
					"L__________L",
					"L__________L",
					"_L________L_",
					"__L______L__",
					"___L____L___",
					"____LLLL____"
					],
					["____________",
					"____L__L____",
					"___L____L___",
					"__L______L__",
					"_L________L_",
					"____________",
					"____________",
					"_L________L_",
					"__L______L__",
					"___L____L___",
					"____L__L____",
					"____________"
					],
					["____________",
					"____L__L____",
					"___L____L___",
					"__L______L__",
					"_L________L_",
					"____________",
					"____________",
					"_L________L_",
					"__L______L__",
					"___L____L___",
					"____L__L____",
					"____________"
					],
					["____________",
					"____________",
					"____LLLL____",
					"___LLLLLL___",
					"__LL____LL__",
					"__LL____LL__",
					"__LL____LL__",
					"__LL____LL__",
					"___LLLLLL___",
					"____LLLL____",
					"____________",
					"____________"
					],
					["____________",
					"____________",
					"____________",
					"____TTTT____",
					"___BLLLLT___",
					"___TLLLLT___",
					"___0LLLLT___",
					"___bLLLLT___",
					"____hTTT____",
					"____________",
					"____________",
					"____________"
					],
					["____________",
					"____________",
					"____________",
					"____________",
					"____TTTT____",
					"____TTTT____",
					"____TTTT____",
					"____TTTT____",
					"____________",
					"____________",
					"____________",
					"____________"
					]
				],
				"symmetrical":true
			}
        },
		{
            "type": "text",
            "text": "If you've let The Greater Egg persuade you into believing that it is close to its peak, and just needs but a little push to help it overcome its middle-of-the-range ''hump'', that can only mean two things:$(li)One, you're looking into actually doing something explicitly for the sake of a $(m)man-made/$ $(m)fake/$ Great Egg $(m)idol/$.$(li)Two, The Greatest Egg is waiting to be awakened and brought forth in all its $(l)Marbled/$ glory, and lead the Eggkind into a new eggra of $(k)aaaa/$...$(k)aaaaaa/$...$(k)a/$...$(k)aaaaaaa/$...$(k)aa"
        },
		{
            "type": "multiblock",
            "name":"The Greatest Egg",
			"text":"The Greatest Egg thanks you for your devotion, and allows barter of 50ml of Seed Oil for two Eggs every 1,25 minutes!",
			"multiblock": {
				"mapping":{
					"0":"modularmachinery:blockcontroller[facing=north]",
					"T":"quark:thatch",
					"b":"modularmachinery:blockinputbus[size=small]",
					"B":"modularmachinery:blockoutputbus[size=small]",
					"h":"modularmachinery:blockfluidinputhatch[size=tiny]",
					"L":"quark:marble[variant=stone_marble]"
				},
				"pattern":[
					["____________",
					"____________",
					"____________",
					"____________",
					"_____LL_____",
					"____LLLL____",
					"____LLLL____",
					"_____LL_____",
					"____________",
					"____________",
					"____________",
					"____________"
					],
					["____________",
					"____________",
					"____________",
					"____LLLL____",
					"___LL__LL___",
					"___L____L___",
					"___L____L___",
					"___LL__LL___",
					"____LLLL____",
					"____________",
					"____________",
					"____________"
					],
					["____________",
					"____________",
					"____LLLL____",
					"___L____L___",
					"__L______L__",
					"__L______L__",
					"__L______L__",
					"__L______L__",
					"___L____L___",
					"____LLLL____",
					"____________",
					"____________"
					],
					["____________",
					"____________",
					"____LLLL____",
					"___L____L___",
					"__L______L__",
					"__L______L__",
					"__L______L__",
					"__L______L__",
					"___L____L___",
					"____LLLL____",
					"____________",
					"____________"
					],
					["____________",
					"____LLLL____",
					"___L____L___",
					"__L______L__",
					"_L________L_",
					"_L________L_",
					"_L________L_",
					"_L________L_",
					"__L______L__",
					"___L____L___",
					"____LLLL____",
					"____________"
					],
					["____________",
					"____LLLL____",
					"___L____L___",
					"__L______L__",
					"_L________L_",
					"_L________L_",
					"_L________L_",
					"_L________L_",
					"__L______L__",
					"___L____L___",
					"____LLLL____",
					"____________"
					],
					["____LLLL____",
					"___L____L___",
					"__L______L__",
					"_L________L_",
					"L__________L",
					"L__________L",
					"L__________L",
					"L__________L",
					"_L________L_",
					"__L______L__",
					"___L____L___",
					"____LLLL____"
					],
					["____LLLL____",
					"___L____L___",
					"__L______L__",
					"_L________L_",
					"L__________L",
					"L__________L",
					"L__________L",
					"L__________L",
					"_L________L_",
					"__L______L__",
					"___L____L___",
					"____LLLL____"
					],
					["____LLLL____",
					"___L____L___",
					"__L______L__",
					"_L________L_",
					"L__________L",
					"L__________L",
					"L__________L",
					"L__________L",
					"_L________L_",
					"__L______L__",
					"___L____L___",
					"____LLLL____"
					],
					["____________",
					"____L__L____",
					"___L____L___",
					"__L______L__",
					"_L________L_",
					"____________",
					"____________",
					"_L________L_",
					"__L______L__",
					"___L____L___",
					"____L__L____",
					"____________"
					],
					["____________",
					"____L__L____",
					"___L____L___",
					"__L______L__",
					"_L________L_",
					"____________",
					"____________",
					"_L________L_",
					"__L______L__",
					"___L____L___",
					"____L__L____",
					"____________"
					],
					["____________",
					"____________",
					"____LLLL____",
					"___LLLLLL___",
					"__LL____LL__",
					"__LL____LL__",
					"__LL____LL__",
					"__LL____LL__",
					"___LLLLLL___",
					"____LLLL____",
					"____________",
					"____________"
					],
					["____________",
					"____________",
					"____________",
					"____TTTT____",
					"___BLLLLT___",
					"___TLLLLT___",
					"___0LLLLT___",
					"___bLLLLT___",
					"____hTTT____",
					"____________",
					"____________",
					"____________"
					],
					["____________",
					"____________",
					"____________",
					"____________",
					"____TTTT____",
					"____TTTT____",
					"____TTTT____",
					"____TTTT____",
					"____________",
					"____________",
					"____________",
					"____________"
					]
				],
				"symmetrical":true
			}
        }
	]
}
		