{
    "registryname": "scp_914_b_11",
    "localizedname": "SCP-914-B (Fine)",
	"color":"676767",
	"modifiers": [
        {
            "x": 0,
            "y": 0,
            "z": 4,
			"elements":	"modularmachinery:blockenergyinputhatch@4",
            "description": "Replace energy hatch blocks with better ones\nto improve the processing time\nat the cost of energy per tick.",
            "modifier": {
                "target": "duration",
                "operation": 1,
                "multiplier": 0.95
            },
			"modifier": {
                "io": "input",
                "target": "energy",
                "operation": 1,
                "multiplier": 1.35
            }
        },
		{
            "x": 1,
            "y": 0,
            "z": 4,
			"elements":	"modularmachinery:blockenergyinputhatch@4",
			"description":"",
            "modifier": {
                "target": "duration",
                "operation": 1,
                "multiplier": 0.95
            },
			"modifier": {
                "io": "input",
                "target": "energy",
                "operation": 1,
                "multiplier": 1.35
            }
        },
		{
            "x": 2,
            "y": 0,
            "z": 4,
			"elements":	"modularmachinery:blockenergyinputhatch@4",
			"description":"",
            "modifier": {
                "target": "duration",
                "operation": 1,
                "multiplier": 0.95
            },
			"modifier": {
                "io": "input",
                "target": "energy",
                "operation": 1,
                "multiplier": 1.35
            }
        },
		{
            "x": 3,
            "y": 0,
            "z": 4,
			"elements":	"modularmachinery:blockenergyinputhatch@4",
			"description":"",
            "modifier": {
                "target": "duration",
                "operation": 1,
                "multiplier": 0.95
            },
			"modifier": {
                "io": "input",
                "target": "energy",
                "operation": 1,
                "multiplier": 1.35
            }
        },
		{
            "x": 0,
            "y": 1,
            "z": 4,
			"elements":	"modularmachinery:blockenergyinputhatch@4",
            "description": "",
            "modifier": {
                "target": "duration",
                "operation": 1,
                "multiplier": 0.95
            },
			"modifier": {
                "io": "input",
                "target": "energy",
                "operation": 1,
                "multiplier": 1.35
            }
        },
		{
            "x": 1,
            "y": 1,
            "z": 4,
			"elements":	"modularmachinery:blockenergyinputhatch@4",
			"description":"",
            "modifier": {
                "target": "duration",
                "operation": 1,
                "multiplier": 0.95
            },
			"modifier": {
                "io": "input",
                "target": "energy",
                "operation": 1,
                "multiplier": 1.35
            }
        },
		{
            "x": 2,
            "y": 1,
            "z": 4,
			"elements":	"modularmachinery:blockenergyinputhatch@4",
			"description":"",
            "modifier": {
                "target": "duration",
                "operation": 1,
                "multiplier": 0.95
            },
			"modifier": {
                "io": "input",
                "target": "energy",
                "operation": 1,
                "multiplier": 1.35
            }
        },
		{
            "x": 3,
            "y": 1,
            "z": 4,
			"elements":	"modularmachinery:blockenergyinputhatch@4",
			"description":"",
            "modifier": {
                "target": "duration",
                "operation": 1,
                "multiplier": 0.95
            },
			"modifier": {
                "io": "input",
                "target": "energy",
                "operation": 1,
                "multiplier": 1.35
            }
        },
		{
            "x": 0,
            "y": 2,
            "z": 4,
			"elements":	"modularmachinery:blockenergyinputhatch@4",
            "description": "",
            "modifier": {
                "target": "duration",
                "operation": 1,
                "multiplier": 0.95
            },
			"modifier": {
                "io": "input",
                "target": "energy",
                "operation": 1,
                "multiplier": 1.35
            }
        },
		{
            "x": 1,
            "y": 2,
            "z": 4,
			"elements":	"modularmachinery:blockenergyinputhatch@4",
			"description":"",
            "modifier": {
                "target": "duration",
                "operation": 1,
                "multiplier": 0.95
            },
			"modifier": {
                "io": "input",
                "target": "energy",
                "operation": 1,
                "multiplier": 1.35
            }
        },
		{
            "x": 2,
            "y": 2,
            "z": 4,
			"elements":	"modularmachinery:blockenergyinputhatch@4",
			"description":"",
            "modifier": {
                "target": "duration",
                "operation": 1,
                "multiplier": 0.95
            },
			"modifier": {
                "io": "input",
                "target": "energy",
                "operation": 1,
                "multiplier": 1.35
            }
        },
		{
            "x": 3,
            "y": 2,
            "z": 4,
			"elements":	"modularmachinery:blockenergyinputhatch@4",
			"description":"",
            "modifier": {
                "target": "duration",
                "operation": 1,
                "multiplier": 0.95
            },
			"modifier": {
                "io": "input",
                "target": "energy",
                "operation": 1,
                "multiplier": 1.35
            }
        },
		{
            "x": 0,
            "y": 0,
            "z": 4,
			"elements":	"modularmachinery:blockenergyinputhatch@5",
            "description": "The hatches can be improved twice.",
            "modifier": {
                "target": "duration",
                "operation": 1,
                "multiplier": 0.9
            },
			"modifier": {
                "io": "input",
                "target": "energy",
                "operation": 1,
                "multiplier": 1.5
            }
        },
		{
            "x": 1,
            "y": 0,
            "z": 4,
			"elements":	"modularmachinery:blockenergyinputhatch@5",
			"description":"",
            "modifier": {
                "target": "duration",
                "operation": 1,
                "multiplier": 0.9
            },
			"modifier": {
                "io": "input",
                "target": "energy",
                "operation": 1,
                "multiplier": 1.5
            }
        },
		{
            "x": 2,
            "y": 0,
            "z": 4,
			"elements":	"modularmachinery:blockenergyinputhatch@5",
			"description":"",
            "modifier": {
                "target": "duration",
                "operation": 1,
                "multiplier": 0.9
            },
			"modifier": {
                "io": "input",
                "target": "energy",
                "operation": 1,
                "multiplier": 1.5
            }
        },
		{
            "x": 3,
            "y": 0,
            "z": 4,
			"elements":	"modularmachinery:blockenergyinputhatch@5",
			"description":"",
            "modifier": {
                "target": "duration",
                "operation": 1,
                "multiplier": 0.9
            },
			"modifier": {
                "io": "input",
                "target": "energy",
                "operation": 1,
                "multiplier": 1.5
            }
        },
		{
            "x": 0,
            "y": 1,
            "z": 4,
			"elements":	"modularmachinery:blockenergyinputhatch@5",
            "description": "",
            "modifier": {
                "target": "duration",
                "operation": 1,
                "multiplier": 0.9
            },
			"modifier": {
                "io": "input",
                "target": "energy",
                "operation": 1,
                "multiplier": 1.5
            }
        },
		{
            "x": 1,
            "y": 1,
            "z": 4,
			"elements":	"modularmachinery:blockenergyinputhatch@5",
			"description":"",
            "modifier": {
                "target": "duration",
                "operation": 1,
                "multiplier": 0.9
            },
			"modifier": {
                "io": "input",
                "target": "energy",
                "operation": 1,
                "multiplier": 1.5
            }
        },
		{
            "x": 2,
            "y": 1,
            "z": 4,
			"elements":	"modularmachinery:blockenergyinputhatch@5",
			"description":"",
            "modifier": {
                "target": "duration",
                "operation": 1,
                "multiplier": 0.9
            },
			"modifier": {
                "io": "input",
                "target": "energy",
                "operation": 1,
                "multiplier": 1.5
            }
        },
		{
            "x": 3,
            "y": 1,
            "z": 4,
			"elements":	"modularmachinery:blockenergyinputhatch@5",
			"description":"",
            "modifier": {
                "target": "duration",
                "operation": 1,
                "multiplier": 0.9
            },
			"modifier": {
                "io": "input",
                "target": "energy",
                "operation": 1,
                "multiplier": 1.5
            }
        },
		{
            "x": 0,
            "y": 2,
            "z": 4,
			"elements":	"modularmachinery:blockenergyinputhatch@5",
            "description": "",
            "modifier": {
                "target": "duration",
                "operation": 1,
                "multiplier": 0.9
            },
			"modifier": {
                "io": "input",
                "target": "energy",
                "operation": 1,
                "multiplier": 1.5
            }
        },
		{
            "x": 1,
            "y": 2,
            "z": 4,
			"elements":	"modularmachinery:blockenergyinputhatch@5",
			"description":"",
            "modifier": {
                "target": "duration",
                "operation": 1,
                "multiplier": 0.9
            },
			"modifier": {
                "io": "input",
                "target": "energy",
                "operation": 1,
                "multiplier": 1.5
            }
        },
		{
            "x": 2,
            "y": 2,
            "z": 4,
			"elements":	"modularmachinery:blockenergyinputhatch@5",
			"description":"",
            "modifier": {
                "target": "duration",
                "operation": 1,
                "multiplier": 0.9
            },
			"modifier": {
                "io": "input",
                "target": "energy",
                "operation": 1,
                "multiplier": 1.5
            }
        },
		{
            "x": 3,
            "y": 2,
            "z": 4,
			"elements":	"modularmachinery:blockenergyinputhatch@5",
			"description":"",
            "modifier": {
                "target": "duration",
                "operation": 1,
                "multiplier": 0.9
            },
			"modifier": {
                "io": "input",
                "target": "energy",
                "operation": 1,
                "multiplier": 1.5
            }
        }
    ],
    "parts": [
        {
            "x": -1,
            "y": 0,
            "z": 0,
            "elements": [
                "immersiveengineering:metal_decoration0@4"
            ]
        },
        {
            "x": 2,
            "y": 4,
            "z": 2,
            "nbt": {"id":"immersiveengineering:ieslab","slabType":"0"},
            "elements": [
                "immersiveengineering:sheetmetal_slab@8"
            ]
        },
        {
            "x": 1,
            "y": 0,
            "z": 0,
            "elements": [
                "immersiveengineering:storage@8"
            ]
        },
        {
            "x": -2,
            "y": 0,
            "z": 0,
            "elements": [
                "immersiveengineering:metal_decoration0@4"
            ]
        },
        {
            "x": 3,
            "y": 4,
            "z": 2,
            "nbt": {"id":"immersiveengineering:ieslab","slabType":"0"},
            "elements": [
                "immersiveengineering:sheetmetal_slab@8"
            ]
        },
        {
            "x": 2,
            "y": 0,
            "z": 0,
            "elements": [
                "immersiveengineering:storage@8"
            ]
        },
        {
            "x": -3,
            "y": 0,
            "z": 0,
            "elements": [
                "stevescarts:blockmetalstorage@2"
            ]
        },
        {
            "x": 4,
            "y": 4,
            "z": 2,
            "nbt": {"id":"immersiveengineering:ieslab","slabType":"0"},
            "elements": [
                "immersiveengineering:sheetmetal_slab@8"
            ]
        },
        {
            "x": 3,
            "y": 0,
            "z": 0,
            "elements": [
                "immersiveengineering:metal_decoration0@3"
            ]
        },
		        {
            "x": 3,
            "y": 0,
            "z": -1,
            "nbt": {"id":"minecraft:comparator","OutputSignal":"11"},
            "elements": [
                "greenpurple_rsinput"
            ]
        },
        {
            "x": -4,
            "y": 0,
            "z": 0,
            "elements": [
                "appliedenergistics2:fluix_block@0"
            ]
        },
        {
            "x": 5,
            "y": 4,
            "z": 2,
            "nbt": {"id":"immersiveengineering:ieslab","slabType":"0"},
            "elements": [
                "immersiveengineering:sheetmetal_slab@8"
            ]
        },
        {
            "x": 4,
            "y": 0,
            "z": 0,
            "elements": [
                "immersiveengineering:metal_decoration0@4"
            ]
        },
        {
            "x": -5,
            "y": 0,
            "z": 0,
            "elements": [
                "stevescarts:blockmetalstorage@2"
            ]
        },
        {
            "x": 6,
            "y": 4,
            "z": 2,
            "elements": [
                "immersiveengineering:metal_device1@6"
            ]
        },
        {
            "x": 5,
            "y": 0,
            "z": 0,
            "elements": [
                "immersiveengineering:metal_decoration0@4"
            ]
        },
        {
            "x": -6,
            "y": 0,
            "z": 0,
            "elements": [
                "immersiveengineering:sheetmetal@8"
            ]
        },
        {
            "x": 7,
            "y": 4,
            "z": 2,
            "elements": [
                "immersiveengineering:metal_device1@6"
            ]
        },
        {
            "x": 6,
            "y": 0,
            "z": 0,
            "elements": [
                "stevescarts:blockmetalstorage@2"
            ]
        },
        {
            "x": 7,
            "y": 0,
            "z": 0,
            "elements": [
                "appliedenergistics2:fluix_block@0"
            ]
        },
        {
            "x": 8,
            "y": 0,
            "z": 0,
            "elements": [
                "stevescarts:blockmetalstorage@2"
            ]
        },
        {
            "x": 9,
            "y": 0,
            "z": 0,
            "elements": [
                "immersiveengineering:sheetmetal@8"
            ]
        },
        {
            "x": 9,
            "y": -1,
            "z": 0,
            "elements": [
                "immersiveengineering:metal_decoration0@4"
            ]
        },
        {
            "x": 8,
            "y": -1,
            "z": 0,
            "elements": [
                "immersiveengineering:sheetmetal@8"
            ]
        },
        {
            "x": 7,
            "y": -1,
            "z": 0,
            "elements": [
                "immersiveengineering:sheetmetal@8"
            ]
        },
        {
            "x": 6,
            "y": -1,
            "z": 0,
            "elements": [
                "immersiveengineering:sheetmetal@8"
            ]
        },
        {
            "x": 5,
            "y": -1,
            "z": 0,
            "elements": [
                "immersiveengineering:sheetmetal@8"
            ]
        },
        {
            "x": -6,
            "y": 1,
            "z": 0,
            "elements": [
                "immersiveengineering:sheetmetal@0"
            ]
        },
        {
            "x": 4,
            "y": -1,
            "z": 0,
            "elements": [
                "immersiveengineering:metal_decoration0@4"
            ]
        },
        {
            "x": -5,
            "y": 1,
            "z": 0,
            "nbt": {"id":"immersiveengineering:ieslab","slabType":"0"},
            "elements": [
                "immersiveengineering:sheetmetal_slab@5"
            ]
        },
        {
            "x": 3,
            "y": -1,
            "z": 0,
            "elements": [
                "immersiveengineering:metal_decoration0@4"
            ]
        },
        {
            "x": -4,
            "y": 1,
            "z": 0,
            "nbt": {"conveyorBeltSubtypeNBT":{"dyeColour":"-1","direction":"0"},"conveyorBeltSubtype":"immersiveengineering:conveyor","id":"immersiveengineering:conveyorbelt"},
            "elements": [
                "immersiveengineering:conveyor@0"
            ]
        },
        {
            "x": 2,
            "y": -1,
            "z": 0,
            "elements": [
                "immersiveengineering:metal_decoration0@4"
            ]
        },
        {
            "x": -3,
            "y": 1,
            "z": 0,
            "nbt": {"conveyorBeltSubtypeNBT":{"dyeColour":"-1","direction":"0"},"conveyorBeltSubtype":"immersiveengineering:conveyor","id":"immersiveengineering:conveyorbelt"},
            "elements": [
                "immersiveengineering:conveyor@0"
            ]
        },
        {
            "x": 1,
            "y": -1,
            "z": 0,
            "elements": [
                "immersiveengineering:metal_decoration0@4"
            ]
        },
        {
            "x": -2,
            "y": 1,
            "z": 0,
            "nbt": {"conveyorBeltSubtypeNBT":{"dyeColour":"-1","direction":"0"},"conveyorBeltSubtype":"immersiveengineering:conveyor","id":"immersiveengineering:conveyorbelt"},
            "elements": [
                "immersiveengineering:conveyor@0"
            ]
        },
        {
            "x": -1,
            "y": 1,
            "z": 0,
            "elements": [
                "immersiveengineering:metal_decoration0@4"
            ]
        },
        {
            "x": 0,
            "y": -1,
            "z": 0,
            "elements": [
                "immersiveengineering:metal_decoration0@4"
            ]
        },
        {
            "x": 0,
            "y": 1,
            "z": 0,
            "elements": [
                "immersiveengineering:storage@8"
            ]
        },
        {
            "x": -1,
            "y": -1,
            "z": 0,
            "elements": [
                "immersiveengineering:metal_decoration0@4"
            ]
        },
        {
            "x": 1,
            "y": 1,
            "z": 0,
            "elements": [
                "immersiveengineering:storage@8"
            ]
        },
        {
            "x": -2,
            "y": -1,
            "z": 0,
            "elements": [
                "immersiveengineering:sheetmetal@8"
            ]
        },
        {
            "x": 2,
            "y": 1,
            "z": 0,
            "elements": [
                "immersiveengineering:storage@8"
            ]
        },
        {
            "x": -3,
            "y": -1,
            "z": 0,
            "elements": [
                "immersiveengineering:sheetmetal@8"
            ]
        },
        {
            "x": 3,
            "y": 1,
            "z": 0,
            "elements": [
                "immersiveengineering:storage@8"
            ]
        },
        {
            "x": -4,
            "y": -1,
            "z": 0,
            "elements": [
                "immersiveengineering:sheetmetal@8"
            ]
        },
        {
            "x": 4,
            "y": 1,
            "z": 0,
            "elements": [
                "immersiveengineering:metal_decoration0@4"
            ]
        },
        {
            "x": -5,
            "y": -1,
            "z": 0,
            "elements": [
                "immersiveengineering:sheetmetal@8"
            ]
        },
        {
            "x": -6,
            "y": -1,
            "z": 0,
            "elements": [
                "immersiveengineering:metal_decoration0@4"
            ]
        },
        {
            "x": 5,
            "y": 1,
            "z": 0,
            "nbt": {"conveyorBeltSubtypeNBT":{"dyeColour":"-1","direction":"0"},"conveyorBeltSubtype":"immersiveengineering:conveyor","id":"immersiveengineering:conveyorbelt"},
            "elements": [
                "immersiveengineering:conveyor@0"
            ]
        },
        {
            "x": 6,
            "y": 1,
            "z": 0,
            "nbt": {"conveyorBeltSubtypeNBT":{"dyeColour":"-1","direction":"0"},"conveyorBeltSubtype":"immersiveengineering:conveyor","id":"immersiveengineering:conveyorbelt"},
            "elements": [
                "immersiveengineering:conveyor@0"
            ]
        },
        {
            "x": 7,
            "y": 1,
            "z": 0,
            "nbt": {"conveyorBeltSubtypeNBT":{"dyeColour":"-1","direction":"0"},"conveyorBeltSubtype":"immersiveengineering:conveyor","id":"immersiveengineering:conveyorbelt"},
            "elements": [
                "immersiveengineering:conveyor@0"
            ]
        },
        {
            "x": 8,
            "y": 1,
            "z": 0,
            "nbt": {"id":"immersiveengineering:ieslab","slabType":"0"},
            "elements": [
                "immersiveengineering:sheetmetal_slab@5"
            ]
        },
        {
            "x": 9,
            "y": 1,
            "z": 0,
            "elements": [
                "immersiveengineering:sheetmetal@0"
            ]
        },
        {
            "x": -6,
            "y": 2,
            "z": 0,
            "elements": [
                "immersiveengineering:sheetmetal@8"
            ]
        },
        {
            "x": -5,
            "y": 2,
            "z": 0,
            "nbt": {"id":"immersiveengineering:ieslab","slabType":"1"},
            "elements": [
                "immersiveengineering:sheetmetal_slab@5"
            ]
        },
        {
            "x": -4,
            "y": 2,
            "z": 0,
            "elements": [
                "immersiveengineering:metal_device1@6"
            ]
        },
        {
            "x": -1,
            "y": 2,
            "z": 0,
            "elements": [
                "immersiveengineering:metal_decoration0@4"
            ]
        },
        {
            "x": 0,
            "y": 2,
            "z": 0,
            "elements": [
                "immersiveengineering:storage@8"
            ]
        },
        {
            "x": 1,
            "y": 2,
            "z": 0,
            "elements": [
                "immersiveengineering:storage@8"
            ]
        },
        {
            "x": 2,
            "y": 2,
            "z": 0,
            "elements": [
                "immersiveengineering:storage@8"
            ]
        },
        {
            "x": 3,
            "y": 2,
            "z": 0,
            "elements": [
                "immersiveengineering:storage@8"
            ]
        },
        {
            "x": 4,
            "y": 2,
            "z": 0,
            "elements": [
                "immersiveengineering:metal_decoration0@4"
            ]
        },
        {
            "x": 7,
            "y": 2,
            "z": 0,
            "elements": [
                "immersiveengineering:metal_device1@6"
            ]
        },
        {
            "x": 8,
            "y": 2,
            "z": 0,
            "nbt": {"id":"immersiveengineering:ieslab","slabType":"1"},
            "elements": [
                "immersiveengineering:sheetmetal_slab@5"
            ]
        },
        {
            "x": 9,
            "y": 2,
            "z": 0,
            "elements": [
                "immersiveengineering:sheetmetal@8"
            ]
        },
        {
            "x": -6,
            "y": 3,
            "z": 0,
            "elements": [
                "immersiveengineering:metal_decoration0@4"
            ]
        },
        {
            "x": -5,
            "y": 3,
            "z": 0,
            "elements": [
                "immersiveengineering:sheetmetal@8"
            ]
        },
        {
            "x": -4,
            "y": 3,
            "z": 0,
            "elements": [
                "immersiveengineering:sheetmetal@8"
            ]
        },
        {
            "x": -3,
            "y": 3,
            "z": 0,
            "elements": [
                "immersiveengineering:sheetmetal@8"
            ]
        },
        {
            "x": -2,
            "y": 3,
            "z": 0,
            "elements": [
                "immersiveengineering:sheetmetal@8"
            ]
        },
        {
            "x": -1,
            "y": 3,
            "z": 0,
            "elements": [
                "immersiveengineering:metal_decoration0@4"
            ]
        },
        {
            "x": 0,
            "y": 3,
            "z": 0,
            "elements": [
                "immersiveengineering:metal_decoration0@4"
            ]
        },
        {
            "x": 1,
            "y": 3,
            "z": 0,
            "elements": [
                "immersiveengineering:metal_decoration0@4"
            ]
        },
        {
            "x": 2,
            "y": 3,
            "z": 0,
            "elements": [
                "immersiveengineering:metal_decoration0@4"
            ]
        },
        {
            "x": 3,
            "y": 3,
            "z": 0,
            "elements": [
                "immersiveengineering:metal_decoration0@4"
            ]
        },
        {
            "x": 4,
            "y": 3,
            "z": 0,
            "elements": [
                "immersiveengineering:metal_decoration0@4"
            ]
        },
        {
            "x": 5,
            "y": 3,
            "z": 0,
            "elements": [
                "immersiveengineering:sheetmetal@8"
            ]
        },
        {
            "x": 6,
            "y": 3,
            "z": 0,
            "elements": [
                "immersiveengineering:sheetmetal@8"
            ]
        },
        {
            "x": 7,
            "y": 3,
            "z": 0,
            "elements": [
                "immersiveengineering:sheetmetal@8"
            ]
        },
        {
            "x": 8,
            "y": 3,
            "z": 0,
            "elements": [
                "immersiveengineering:sheetmetal@8"
            ]
        },
        {
            "x": 9,
            "y": 3,
            "z": 0,
            "elements": [
                "immersiveengineering:metal_decoration0@4"
            ]
        },
        {
            "x": -5,
            "y": 4,
            "z": 0,
            "elements": [
                "immersiveengineering:metal_device1@6"
            ]
        },
        {
            "x": -4,
            "y": 4,
            "z": 0,
            "nbt": {"id":"immersiveengineering:ieslab","slabType":"0"},
            "elements": [
                "immersiveengineering:sheetmetal_slab@8"
            ]
        },
        {
            "x": -3,
            "y": 4,
            "z": 0,
            "nbt": {"id":"immersiveengineering:ieslab","slabType":"0"},
            "elements": [
                "immersiveengineering:sheetmetal_slab@8"
            ]
        },
        {
            "x": -2,
            "y": 4,
            "z": 0,
            "nbt": {"id":"immersiveengineering:ieslab","slabType":"0"},
            "elements": [
                "immersiveengineering:sheetmetal_slab@8"
            ]
        },
        {
            "x": 5,
            "y": 4,
            "z": 0,
            "nbt": {"id":"immersiveengineering:ieslab","slabType":"0"},
            "elements": [
                "immersiveengineering:sheetmetal_slab@8"
            ]
        },
        {
            "x": 6,
            "y": 4,
            "z": 0,
            "nbt": {"id":"immersiveengineering:ieslab","slabType":"0"},
            "elements": [
                "immersiveengineering:sheetmetal_slab@8"
            ]
        },
        {
            "x": 7,
            "y": 4,
            "z": 0,
            "nbt": {"id":"immersiveengineering:ieslab","slabType":"0"},
            "elements": [
                "immersiveengineering:sheetmetal_slab@8"
            ]
        },
        {
            "x": 8,
            "y": 4,
            "z": 0,
            "elements": [
                "immersiveengineering:metal_device1@6"
            ]
        },
        {
            "x": 9,
            "y": 4,
            "z": -9,
            "elements": [
                "immersiveengineering:metal_device1@6"
            ]
        },
        {
            "x": 8,
            "y": 4,
            "z": -9,
            "nbt": {"id":"immersiveengineering:ieslab","slabType":"0"},
            "elements": [
                "immersiveengineering:sheetmetal_slab@8"
            ]
        },
        {
            "x": 7,
            "y": 4,
            "z": -9,
            "elements": [
                "immersiveengineering:metal_device1@6"
            ]
        },
        {
            "x": 6,
            "y": 4,
            "z": -9,
            "elements": [
                "immersiveengineering:metal_device1@6"
            ]
        },
        {
            "x": 5,
            "y": 4,
            "z": -9,
            "elements": [
                "immersiveengineering:metal_device1@6"
            ]
        },
        {
            "x": -2,
            "y": 4,
            "z": -9,
            "elements": [
                "immersiveengineering:metal_device1@6"
            ]
        },
        {
            "x": -3,
            "y": 4,
            "z": -9,
            "elements": [
                "immersiveengineering:metal_device1@6"
            ]
        },
        {
            "x": -4,
            "y": 4,
            "z": -9,
            "elements": [
                "immersiveengineering:metal_device1@6"
            ]
        },
        {
            "x": -5,
            "y": 4,
            "z": -9,
            "nbt": {"id":"immersiveengineering:ieslab","slabType":"0"},
            "elements": [
                "immersiveengineering:sheetmetal_slab@8"
            ]
        },
        {
            "x": -6,
            "y": 4,
            "z": -9,
            "elements": [
                "immersiveengineering:metal_device1@6"
            ]
        },
        {
            "x": -7,
            "y": 4,
            "z": -9,
            "elements": [
                "immersiveengineering:metal_device1@6"
            ]
        },
        {
            "x": -8,
            "y": 4,
            "z": -9,
            "elements": [
                "immersiveengineering:metal_device1@6"
            ]
        },
        {
            "x": 10,
            "y": 3,
            "z": -9,
            "elements": [
                "immersiveengineering:metal_decoration0@4"
            ]
        },
        {
            "x": 9,
            "y": 3,
            "z": -9,
            "elements": [
                "immersiveengineering:metal_device1@6"
            ]
        },
        {
            "x": 8,
            "y": 3,
            "z": -9,
            "elements": [
                "immersiveengineering:sheetmetal@8"
            ]
        },
        {
            "x": 7,
            "y": 3,
            "z": -9,
            "elements": [
                "immersiveengineering:metal_device1@6"
            ]
        },
        {
            "x": 6,
            "y": 3,
            "z": -9,
            "elements": [
                "immersiveengineering:metal_decoration0@4"
            ]
        },
        {
            "x": 5,
            "y": 3,
            "z": -9,
            "elements": [
                "immersiveengineering:metal_device1@6"
            ]
        },
        {
            "x": -2,
            "y": 3,
            "z": -9,
            "elements": [
                "immersiveengineering:metal_device1@6"
            ]
        },
        {
            "x": -3,
            "y": 3,
            "z": -9,
            "elements": [
                "immersiveengineering:metal_decoration0@4"
            ]
        },
        {
            "x": -4,
            "y": 3,
            "z": -9,
            "elements": [
                "immersiveengineering:metal_device1@6"
            ]
        },
        {
            "x": -5,
            "y": 3,
            "z": -9,
            "elements": [
                "immersiveengineering:sheetmetal@8"
            ]
        },
        {
            "x": -6,
            "y": 3,
            "z": -9,
            "elements": [
                "immersiveengineering:sheetmetal@8"
            ]
        },
        {
            "x": -7,
            "y": 3,
            "z": -9,
            "elements": [
                "immersiveengineering:metal_decoration0@4"
            ]
        },
        {
            "x": -8,
            "y": 3,
            "z": -9,
            "elements": [
                "immersiveengineering:metal_device1@6"
            ]
        },
        {
            "x": 10,
            "y": 2,
            "z": -9,
            "elements": [
                "immersiveengineering:sheetmetal@8"
            ]
        },
        {
            "x": 9,
            "y": 2,
            "z": -9,
            "elements": [
                "greenpurple_hatchinput"
            ]
        },
        {
            "x": 8,
            "y": 2,
            "z": -9,
            "elements": [
                "greenpurple_hatchinput"
            ]
        },
        {
            "x": 7,
            "y": 2,
            "z": -9,
            "elements": [
                "greenpurple_hatchinput"
            ]
        },
        {
            "x": 6,
            "y": 2,
            "z": -9,
            "elements": [
                "immersiveengineering:sheetmetal@8"
            ]
        },
        {
            "x": -3,
            "y": 2,
            "z": -9,
            "elements": [
                "immersiveengineering:sheetmetal@8"
            ]
        },
        {
            "x": -4,
            "y": 2,
            "z": -9,
            "elements": [
                "greenpurple_hatchoutput"
            ]
        },
        {
            "x": -5,
            "y": 2,
            "z": -9,
            "elements": [
                "greenpurple_hatchoutput"
            ]
        },
        {
            "x": -6,
            "y": 2,
            "z": -9,
            "elements": [
                "greenpurple_hatchoutput"
            ]
        },
        {
            "x": -7,
            "y": 2,
            "z": -9,
            "elements": [
                "immersiveengineering:metal_device1@6"
            ]
        },
        {
            "x": -8,
            "y": 2,
            "z": -9,
            "elements": [
                "immersiveengineering:metal_device1@6"
            ]
        },
        {
            "x": 10,
            "y": 1,
            "z": -9,
            "elements": [
                "immersiveengineering:sheetmetal@8"
            ]
        },
        {
            "x": 9,
            "y": 1,
            "z": -9,
            "elements": [
                "greenpurple_hatchinput"
            ]
        },
        {
            "x": 8,
            "y": 1,
            "z": -9,
            "elements": [
                "greenpurple_businput"
            ]
        },
        {
            "x": 7,
            "y": 1,
            "z": -9,
            "elements": [
                "greenpurple_businput"
            ]
        },
        {
            "x": 6,
            "y": 1,
            "z": -9,
            "elements": [
                "immersiveengineering:sheetmetal@8"
            ]
        },
        {
            "x": -3,
            "y": 1,
            "z": -9,
            "elements": [
                "immersiveengineering:sheetmetal@8"
            ]
        },
        {
            "x": -4,
            "y": 1,
            "z": -9,
            "elements": [
                "greenpurple_busoutput"
            ]
        },
        {
            "x": -5,
            "y": 1,
            "z": -9,
             "elements": [
                "greenpurple_busoutput"
            ]
        },
        {
            "x": -6,
            "y": 1,
            "z": -9,
            "elements": [
                "greenpurple_hatchoutput"
            ]
        },
        {
            "x": -7,
            "y": 1,
            "z": -9,
            "elements": [
                "immersiveengineering:sheetmetal@8"
            ]
        },
        {
            "x": 10,
            "y": 0,
            "z": -9,
            "elements": [
                "immersiveengineering:sheetmetal@8"
            ]
        },
        {
            "x": 9,
            "y": 0,
            "z": -9,
            "elements": [
                "greenpurple_businput"
            ]
        },
        {
            "x": 8,
            "y": 0,
            "z": -9,
             "elements": [
                "greenpurple_businput"
            ]
        },
        {
            "x": 7,
            "y": 0,
            "z": -9,
            "elements": [
                "greenpurple_businput"
            ]
        },
        {
            "x": 9,
            "y": 4,
            "z": -7,
            "elements": [
                "immersiveengineering:metal_device1@6"
            ]
        },
        {
            "x": 6,
            "y": 0,
            "z": -9,
            "elements": [
                "immersiveengineering:sheetmetal@8"
            ]
        },
        {
            "x": 8,
            "y": 4,
            "z": -7,
            "nbt": {"id":"immersiveengineering:ieslab","slabType":"0"},
            "elements": [
                "immersiveengineering:sheetmetal_slab@8"
            ]
        },
        {
            "x": 7,
            "y": 4,
            "z": -7,
            "nbt": {"id":"immersiveengineering:ieslab","slabType":"0"},
            "elements": [
                "immersiveengineering:sheetmetal_slab@8"
            ]
        },
        {
            "x": -3,
            "y": 0,
            "z": -9,
            "elements": [
                "immersiveengineering:sheetmetal@8"
            ]
        },
        {
            "x": -4,
            "y": 0,
            "z": -9,
            "elements": [
                "greenpurple_busoutput"
            ]
        },
        {
            "x": -5,
            "y": 0,
            "z": -9,
             "elements": [
                "greenpurple_busoutput"
            ]
        },
        {
            "x": -6,
            "y": 0,
            "z": -9,
            "elements": [
                "greenpurple_busoutput"
            ]
        },
        {
            "x": -4,
            "y": 4,
            "z": -7,
            "nbt": {"id":"immersiveengineering:ieslab","slabType":"0"},
            "elements": [
                "immersiveengineering:sheetmetal_slab@8"
            ]
        },
        {
            "x": -7,
            "y": 0,
            "z": -9,
            "elements": [
                "immersiveengineering:sheetmetal@8"
            ]
        },
        {
            "x": -5,
            "y": 4,
            "z": -7,
            "nbt": {"id":"immersiveengineering:ieslab","slabType":"0"},
            "elements": [
                "immersiveengineering:sheetmetal_slab@8"
            ]
        },
        {
            "x": -6,
            "y": 4,
            "z": -7,
            "elements": [
                "immersiveengineering:metal_device1@6"
            ]
        },
        {
            "x": 10,
            "y": -1,
            "z": -9,
            "elements": [
                "immersiveengineering:metal_decoration0@4"
            ]
        },
        {
            "x": 9,
            "y": -1,
            "z": -9,
            "elements": [
                "immersiveengineering:sheetmetal@8"
            ]
        },
        {
            "x": 8,
            "y": -1,
            "z": -9,
            "elements": [
                "immersiveengineering:sheetmetal@8"
            ]
        },
        {
            "x": 10,
            "y": 3,
            "z": -7,
            "elements": [
                "immersiveengineering:metal_decoration0@4"
            ]
        },
        {
            "x": 7,
            "y": -1,
            "z": -9,
            "elements": [
                "immersiveengineering:sheetmetal@8"
            ]
        },
        {
            "x": 9,
            "y": 3,
            "z": -7,
            "elements": [
                "immersiveengineering:sheetmetal@8"
            ]
        },
        {
            "x": 6,
            "y": -1,
            "z": -9,
            "elements": [
                "immersiveengineering:metal_decoration0@4"
            ]
        },
        {
            "x": 8,
            "y": 3,
            "z": -7,
            "elements": [
                "immersiveengineering:sheetmetal@8"
            ]
        },
        {
            "x": 7,
            "y": 3,
            "z": -7,
            "elements": [
                "immersiveengineering:sheetmetal@8"
            ]
        },
        {
            "x": 6,
            "y": 3,
            "z": -7,
            "elements": [
                "immersiveengineering:metal_decoration0@4"
            ]
        },
        {
            "x": 5,
            "y": 3,
            "z": -7,
            "elements": [
                "immersiveengineering:metal_device1@6"
            ]
        },
        {
            "x": -3,
            "y": -1,
            "z": -9,
            "elements": [
                "immersiveengineering:metal_decoration0@4"
            ]
        },
        {
            "x": -4,
            "y": -1,
            "z": -9,
            "elements": [
                "immersiveengineering:sheetmetal@8"
            ]
        },
        {
            "x": -2,
            "y": 3,
            "z": -7,
            "elements": [
                "immersiveengineering:metal_device1@6"
            ]
        },
        {
            "x": -5,
            "y": -1,
            "z": -9,
            "elements": [
                "immersiveengineering:sheetmetal@8"
            ]
        },
        {
            "x": -3,
            "y": 3,
            "z": -7,
            "elements": [
                "immersiveengineering:metal_decoration0@4"
            ]
        },
        {
            "x": -6,
            "y": -1,
            "z": -9,
            "elements": [
                "immersiveengineering:sheetmetal@8"
            ]
        },
        {
            "x": -4,
            "y": 3,
            "z": -7,
            "elements": [
                "immersiveengineering:sheetmetal@8"
            ]
        },
        {
            "x": -7,
            "y": -1,
            "z": -9,
            "elements": [
                "immersiveengineering:metal_decoration0@4"
            ]
        },
        {
            "x": -5,
            "y": 3,
            "z": -7,
            "elements": [
                "immersiveengineering:sheetmetal@8"
            ]
        },
        {
            "x": -6,
            "y": 3,
            "z": -7,
            "elements": [
                "immersiveengineering:sheetmetal@8"
            ]
        },
        {
            "x": -7,
            "y": 3,
            "z": -7,
            "elements": [
                "immersiveengineering:metal_decoration0@4"
            ]
        },
        {
            "x": 10,
            "y": 2,
            "z": -7,
            "elements": [
                "immersiveengineering:sheetmetal@8"
            ]
        },
        {
            "x": 9,
            "y": 2,
            "z": -7,
            "nbt": {"id":"immersiveengineering:ieslab","slabType":"1"},
            "elements": [
                "immersiveengineering:sheetmetal_slab@5"
            ]
        },
        {
            "x": 8,
            "y": 2,
            "z": -7,
            "elements": [
                "immersiveengineering:metal_device1@6"
            ]
        },
        {
            "x": 6,
            "y": 2,
            "z": -7,
            "elements": [
                "immersiveengineering:sheetmetal@8"
            ]
        },
        {
            "x": -3,
            "y": 2,
            "z": -7,
            "elements": [
                "immersiveengineering:sheetmetal@8"
            ]
        },
        {
            "x": -5,
            "y": 2,
            "z": -7,
            "elements": [
                "immersiveengineering:metal_device1@6"
            ]
        },
        {
            "x": -6,
            "y": 2,
            "z": -7,
            "nbt": {"id":"immersiveengineering:ieslab","slabType":"1"},
            "elements": [
                "immersiveengineering:sheetmetal_slab@5"
            ]
        },
        {
            "x": -7,
            "y": 2,
            "z": -7,
            "elements": [
                "immersiveengineering:sheetmetal@8"
            ]
        },
        {
            "x": 10,
            "y": 1,
            "z": -7,
            "elements": [
                "immersiveengineering:sheetmetal@0"
            ]
        },
        {
            "x": 9,
            "y": 1,
            "z": -7,
            "nbt": {"id":"immersiveengineering:ieslab","slabType":"0"},
            "elements": [
                "immersiveengineering:sheetmetal_slab@5"
            ]
        },
        {
            "x": 8,
            "y": 1,
            "z": -7,
            "nbt": {"conveyorBeltSubtypeNBT":{"dyeColour":"-1","direction":"0"},"conveyorBeltSubtype":"immersiveengineering:conveyor","id":"immersiveengineering:conveyorbelt"},
            "elements": [
                "immersiveengineering:conveyor@0"
            ]
        },
        {
            "x": 7,
            "y": 1,
            "z": -7,
            "nbt": {"conveyorBeltSubtypeNBT":{"dyeColour":"-1","direction":"0"},"conveyorBeltSubtype":"immersiveengineering:conveyor","id":"immersiveengineering:conveyorbelt"},
            "elements": [
                "immersiveengineering:conveyor@0"
            ]
        },
        {
            "x": 6,
            "y": 1,
            "z": -7,
            "elements": [
                "thermalfoundation:glass@3"
            ]
        },
        {
            "x": -3,
            "y": 1,
            "z": -7,
            "elements": [
                "thermalfoundation:glass@3"
            ]
        },
        {
            "x": -4,
            "y": 1,
            "z": -7,
            "nbt": {"conveyorBeltSubtypeNBT":{"dyeColour":"-1","direction":"0"},"conveyorBeltSubtype":"immersiveengineering:conveyor","id":"immersiveengineering:conveyorbelt"},
            "elements": [
                "immersiveengineering:conveyor@0"
            ]
        },
        {
            "x": -5,
            "y": 1,
            "z": -7,
            "nbt": {"conveyorBeltSubtypeNBT":{"dyeColour":"-1","direction":"0"},"conveyorBeltSubtype":"immersiveengineering:conveyor","id":"immersiveengineering:conveyorbelt"},
            "elements": [
                "immersiveengineering:conveyor@0"
            ]
        },
        {
            "x": -6,
            "y": 1,
            "z": -7,
            "nbt": {"id":"immersiveengineering:ieslab","slabType":"0"},
            "elements": [
                "immersiveengineering:sheetmetal_slab@5"
            ]
        },
        {
            "x": -7,
            "y": 1,
            "z": -7,
            "elements": [
                "immersiveengineering:sheetmetal@0"
            ]
        },
        {
            "x": 10,
            "y": 0,
            "z": -7,
            "elements": [
                "immersiveengineering:sheetmetal@8"
            ]
        },
        {
            "x": 9,
            "y": 0,
            "z": -7,
            "elements": [
                "stevescarts:blockmetalstorage@2"
            ]
        },
        {
            "x": 8,
            "y": 0,
            "z": -7,
            "elements": [
                "appliedenergistics2:fluix_block@0"
            ]
        },
        {
            "x": 7,
            "y": 0,
            "z": -7,
            "elements": [
                "stevescarts:blockmetalstorage@2"
            ]
        },
        {
            "x": 9,
            "y": 4,
            "z": -5,
            "elements": [
                "immersiveengineering:metal_device1@6"
            ]
        },
        {
            "x": 6,
            "y": 0,
            "z": -7,
            "elements": [
                "immersiveengineering:sheetmetal@8"
            ]
        },
        {
            "x": 8,
            "y": 4,
            "z": -5,
            "nbt": {"id":"immersiveengineering:ieslab","slabType":"0"},
            "elements": [
                "immersiveengineering:sheetmetal_slab@8"
            ]
        },
        {
            "x": 7,
            "y": 4,
            "z": -5,
            "nbt": {"id":"immersiveengineering:ieslab","slabType":"0"},
            "elements": [
                "immersiveengineering:sheetmetal_slab@8"
            ]
        },
        {
            "x": -3,
            "y": 0,
            "z": -7,
            "elements": [
                "immersiveengineering:sheetmetal@8"
            ]
        },
        {
            "x": -4,
            "y": 0,
            "z": -7,
            "elements": [
                "stevescarts:blockmetalstorage@2"
            ]
        },
        {
            "x": -5,
            "y": 0,
            "z": -7,
            "elements": [
                "appliedenergistics2:fluix_block@0"
            ]
        },
        {
            "x": -6,
            "y": 0,
            "z": -7,
            "elements": [
                "stevescarts:blockmetalstorage@2"
            ]
        },
        {
            "x": -4,
            "y": 4,
            "z": -5,
            "nbt": {"id":"immersiveengineering:ieslab","slabType":"0"},
            "elements": [
                "immersiveengineering:sheetmetal_slab@8"
            ]
        },
        {
            "x": -7,
            "y": 0,
            "z": -7,
            "elements": [
                "immersiveengineering:sheetmetal@8"
            ]
        },
        {
            "x": -5,
            "y": 4,
            "z": -5,
            "nbt": {"id":"immersiveengineering:ieslab","slabType":"0"},
            "elements": [
                "immersiveengineering:sheetmetal_slab@8"
            ]
        },
        {
            "x": -6,
            "y": 4,
            "z": -5,
            "elements": [
                "immersiveengineering:metal_device1@6"
            ]
        },
        {
            "x": 10,
            "y": -1,
            "z": -7,
            "elements": [
                "immersiveengineering:metal_decoration0@4"
            ]
        },
        {
            "x": 9,
            "y": -1,
            "z": -7,
            "elements": [
                "immersiveengineering:sheetmetal@8"
            ]
        },
        {
            "x": 8,
            "y": -1,
            "z": -7,
            "elements": [
                "immersiveengineering:sheetmetal@8"
            ]
        },
        {
            "x": 10,
            "y": 3,
            "z": -5,
            "elements": [
                "immersiveengineering:metal_decoration0@4"
            ]
        },
        {
            "x": 7,
            "y": -1,
            "z": -7,
            "elements": [
                "immersiveengineering:sheetmetal@8"
            ]
        },
        {
            "x": 9,
            "y": 3,
            "z": -5,
            "elements": [
                "immersiveengineering:sheetmetal@8"
            ]
        },
        {
            "x": 6,
            "y": -1,
            "z": -7,
            "elements": [
                "immersiveengineering:metal_decoration0@4"
            ]
        },
        {
            "x": 8,
            "y": 3,
            "z": -5,
            "elements": [
                "immersiveengineering:sheetmetal@8"
            ]
        },
        {
            "x": 7,
            "y": 3,
            "z": -5,
            "elements": [
                "immersiveengineering:sheetmetal@8"
            ]
        },
        {
            "x": 6,
            "y": 3,
            "z": -5,
            "elements": [
                "immersiveengineering:metal_decoration0@4"
            ]
        },
        {
            "x": 5,
            "y": 3,
            "z": -5,
            "elements": [
                "immersiveengineering:metal_device1@6"
            ]
        },
        {
            "x": -3,
            "y": -1,
            "z": -7,
            "elements": [
                "immersiveengineering:metal_decoration0@4"
            ]
        },
        {
            "x": -4,
            "y": -1,
            "z": -7,
            "elements": [
                "immersiveengineering:sheetmetal@8"
            ]
        },
        {
            "x": -2,
            "y": 3,
            "z": -5,
            "elements": [
                "immersiveengineering:metal_device1@6"
            ]
        },
        {
            "x": -5,
            "y": -1,
            "z": -7,
            "elements": [
                "immersiveengineering:sheetmetal@8"
            ]
        },
        {
            "x": -3,
            "y": 3,
            "z": -5,
            "elements": [
                "immersiveengineering:metal_decoration0@4"
            ]
        },
        {
            "x": -6,
            "y": -1,
            "z": -7,
            "elements": [
                "immersiveengineering:sheetmetal@8"
            ]
        },
        {
            "x": -4,
            "y": 3,
            "z": -5,
            "elements": [
                "immersiveengineering:sheetmetal@8"
            ]
        },
        {
            "x": -7,
            "y": -1,
            "z": -7,
            "elements": [
                "immersiveengineering:metal_decoration0@4"
            ]
        },
        {
            "x": -5,
            "y": 3,
            "z": -5,
            "elements": [
                "immersiveengineering:sheetmetal@8"
            ]
        },
        {
            "x": -6,
            "y": 3,
            "z": -5,
            "elements": [
                "immersiveengineering:sheetmetal@8"
            ]
        },
        {
            "x": -7,
            "y": 3,
            "z": -5,
            "elements": [
                "immersiveengineering:metal_decoration0@4"
            ]
        },
        {
            "x": 10,
            "y": 2,
            "z": -5,
            "elements": [
                "immersiveengineering:sheetmetal@8"
            ]
        },
        {
            "x": 9,
            "y": 2,
            "z": -5,
            "nbt": {"id":"immersiveengineering:ieslab","slabType":"1"},
            "elements": [
                "immersiveengineering:sheetmetal_slab@5"
            ]
        },
        {
            "x": 8,
            "y": 2,
            "z": -5,
            "elements": [
                "immersiveengineering:metal_device1@6"
            ]
        },
        {
            "x": 6,
            "y": 2,
            "z": -5,
            "elements": [
                "immersiveengineering:sheetmetal@8"
            ]
        },
        {
            "x": -3,
            "y": 2,
            "z": -5,
            "elements": [
                "immersiveengineering:sheetmetal@8"
            ]
        },
        {
            "x": -5,
            "y": 2,
            "z": -5,
            "elements": [
                "immersiveengineering:metal_device1@6"
            ]
        },
        {
            "x": -6,
            "y": 2,
            "z": -5,
            "nbt": {"id":"immersiveengineering:ieslab","slabType":"1"},
            "elements": [
                "immersiveengineering:sheetmetal_slab@5"
            ]
        },
        {
            "x": -7,
            "y": 2,
            "z": -5,
            "elements": [
                "immersiveengineering:sheetmetal@8"
            ]
        },
        {
            "x": 10,
            "y": 1,
            "z": -5,
            "elements": [
                "immersiveengineering:sheetmetal@0"
            ]
        },
        {
            "x": 9,
            "y": 1,
            "z": -5,
            "nbt": {"id":"immersiveengineering:ieslab","slabType":"0"},
            "elements": [
                "immersiveengineering:sheetmetal_slab@5"
            ]
        },
        {
            "x": 8,
            "y": 1,
            "z": -5,
            "nbt": {"conveyorBeltSubtypeNBT":{"dyeColour":"-1","direction":"0"},"conveyorBeltSubtype":"immersiveengineering:conveyor","id":"immersiveengineering:conveyorbelt"},
            "elements": [
                "immersiveengineering:conveyor@0"
            ]
        },
        {
            "x": 7,
            "y": 1,
            "z": -5,
            "nbt": {"conveyorBeltSubtypeNBT":{"dyeColour":"-1","direction":"0"},"conveyorBeltSubtype":"immersiveengineering:conveyor","id":"immersiveengineering:conveyorbelt"},
            "elements": [
                "immersiveengineering:conveyor@0"
            ]
        },
        {
            "x": 6,
            "y": 1,
            "z": -5,
            "elements": [
                "thermalfoundation:glass@3"
            ]
        },
        {
            "x": -1,
            "y": -1,
            "z": 5,
            "elements": [
                "immersiveengineering:stone_decoration@8"
            ]
        },
        {
            "x": 0,
            "y": -1,
            "z": 5,
            "elements": [
                "immersiveengineering:metal_decoration0@5"
            ]
        },
        {
            "x": 1,
            "y": -1,
            "z": 5,
            "elements": [
                "immersiveengineering:metal_decoration0@5"
            ]
        },
        {
            "x": 2,
            "y": -1,
            "z": 5,
            "elements": [
                "immersiveengineering:metal_decoration0@5"
            ]
        },
        {
            "x": -3,
            "y": 1,
            "z": -5,
            "elements": [
                "thermalfoundation:glass@3"
            ]
        },
        {
            "x": 3,
            "y": -1,
            "z": 5,
            "elements": [
                "immersiveengineering:metal_decoration0@5"
            ]
        },
        {
            "x": -4,
            "y": 1,
            "z": -5,
            "nbt": {"conveyorBeltSubtypeNBT":{"dyeColour":"-1","direction":"0"},"conveyorBeltSubtype":"immersiveengineering:conveyor","id":"immersiveengineering:conveyorbelt"},
            "elements": [
                "immersiveengineering:conveyor@0"
            ]
        },
        {
            "x": 4,
            "y": -1,
            "z": 5,
            "elements": [
                "immersiveengineering:stone_decoration@8"
            ]
        },
        {
            "x": -5,
            "y": 1,
            "z": -5,
            "nbt": {"conveyorBeltSubtypeNBT":{"dyeColour":"-1","direction":"0"},"conveyorBeltSubtype":"immersiveengineering:conveyor","id":"immersiveengineering:conveyorbelt"},
            "elements": [
                "immersiveengineering:conveyor@0"
            ]
        },
        {
            "x": -6,
            "y": 1,
            "z": -5,
            "nbt": {"id":"immersiveengineering:ieslab","slabType":"0"},
            "elements": [
                "immersiveengineering:sheetmetal_slab@5"
            ]
        },
        {
            "x": -7,
            "y": 1,
            "z": -5,
            "elements": [
                "immersiveengineering:sheetmetal@0"
            ]
        },
        {
            "x": 10,
            "y": 0,
            "z": -5,
            "elements": [
                "immersiveengineering:sheetmetal@8"
            ]
        },
        {
            "x": 9,
            "y": 0,
            "z": -5,
            "elements": [
                "stevescarts:blockmetalstorage@2"
            ]
        },
        {
            "x": 8,
            "y": 0,
            "z": -5,
            "elements": [
                "appliedenergistics2:fluix_block@0"
            ]
        },
        {
            "x": 7,
            "y": 0,
            "z": -5,
            "elements": [
                "stevescarts:blockmetalstorage@2"
            ]
        },
        {
            "x": 9,
            "y": 4,
            "z": -3,
            "elements": [
                "immersiveengineering:metal_device1@6"
            ]
        },
        {
            "x": 6,
            "y": 0,
            "z": -5,
            "elements": [
                "immersiveengineering:sheetmetal@8"
            ]
        },
        {
            "x": 8,
            "y": 4,
            "z": -3,
            "nbt": {"id":"immersiveengineering:ieslab","slabType":"0"},
            "elements": [
                "immersiveengineering:sheetmetal_slab@8"
            ]
        },
        {
            "x": 7,
            "y": 4,
            "z": -3,
            "nbt": {"id":"immersiveengineering:ieslab","slabType":"0"},
            "elements": [
                "immersiveengineering:sheetmetal_slab@8"
            ]
        },
        {
            "x": -1,
            "y": 0,
            "z": 5,
            "elements": [
                "immersiveengineering:metal_decoration0@2"
            ]
        },
        {
            "x": -3,
            "y": 0,
            "z": -5,
            "elements": [
                "immersiveengineering:sheetmetal@8"
            ]
        },
        {
            "x": -4,
            "y": 0,
            "z": -5,
            "elements": [
                "stevescarts:blockmetalstorage@2"
            ]
        },
        {
            "x": -5,
            "y": 0,
            "z": -5,
            "elements": [
                "appliedenergistics2:fluix_block@0"
            ]
        },
        {
            "x": 4,
            "y": 0,
            "z": 5,
            "elements": [
                "immersiveengineering:metal_decoration0@2"
            ]
        },
        {
            "x": -6,
            "y": 0,
            "z": -5,
            "elements": [
                "stevescarts:blockmetalstorage@2"
            ]
        },
        {
            "x": -4,
            "y": 4,
            "z": -3,
            "nbt": {"id":"immersiveengineering:ieslab","slabType":"0"},
            "elements": [
                "immersiveengineering:sheetmetal_slab@8"
            ]
        },
        {
            "x": -7,
            "y": 0,
            "z": -5,
            "elements": [
                "immersiveengineering:sheetmetal@8"
            ]
        },
        {
            "x": -5,
            "y": 4,
            "z": -3,
            "nbt": {"id":"immersiveengineering:ieslab","slabType":"0"},
            "elements": [
                "immersiveengineering:sheetmetal_slab@8"
            ]
        },
        {
            "x": -6,
            "y": 4,
            "z": -3,
            "elements": [
                "immersiveengineering:metal_device1@6"
            ]
        },
        {
            "x": 10,
            "y": -1,
            "z": -5,
            "elements": [
                "immersiveengineering:metal_decoration0@4"
            ]
        },
        {
            "x": 9,
            "y": -1,
            "z": -5,
            "elements": [
                "immersiveengineering:sheetmetal@8"
            ]
        },
        {
            "x": 8,
            "y": -1,
            "z": -5,
            "elements": [
                "immersiveengineering:sheetmetal@8"
            ]
        },
        {
            "x": 10,
            "y": 3,
            "z": -3,
            "elements": [
                "immersiveengineering:metal_decoration0@4"
            ]
        },
        {
            "x": 7,
            "y": -1,
            "z": -5,
            "elements": [
                "immersiveengineering:sheetmetal@8"
            ]
        },
        {
            "x": 9,
            "y": 3,
            "z": -3,
            "elements": [
                "immersiveengineering:sheetmetal@8"
            ]
        },
        {
            "x": 6,
            "y": -1,
            "z": -5,
            "elements": [
                "immersiveengineering:metal_decoration0@4"
            ]
        },
        {
            "x": 8,
            "y": 3,
            "z": -3,
            "elements": [
                "immersiveengineering:sheetmetal@8"
            ]
        },
        {
            "x": 7,
            "y": 3,
            "z": -3,
            "elements": [
                "immersiveengineering:sheetmetal@8"
            ]
        },
        {
            "x": 6,
            "y": 3,
            "z": -3,
            "elements": [
                "immersiveengineering:metal_decoration0@4"
            ]
        },
        {
            "x": 5,
            "y": 3,
            "z": -3,
            "elements": [
                "immersiveengineering:metal_device1@6"
            ]
        },
        {
            "x": 4,
            "y": 3,
            "z": -3,
            "elements": [
                "immersiveengineering:metal_device1@6"
            ]
        },
        {
            "x": -1,
            "y": 1,
            "z": 5,
            "elements": [
                "immersiveengineering:metal_decoration0@2"
            ]
        },
        {
            "x": -3,
            "y": -1,
            "z": -5,
            "elements": [
                "immersiveengineering:metal_decoration0@4"
            ]
        },
        {
            "x": -1,
            "y": 3,
            "z": -3,
            "elements": [
                "immersiveengineering:metal_device1@6"
            ]
        },
        {
            "x": -4,
            "y": -1,
            "z": -5,
            "elements": [
                "immersiveengineering:sheetmetal@8"
            ]
        },
        {
            "x": -2,
            "y": 3,
            "z": -3,
            "elements": [
                "immersiveengineering:metal_device1@6"
            ]
        },
        {
            "x": -5,
            "y": -1,
            "z": -5,
            "elements": [
                "immersiveengineering:sheetmetal@8"
            ]
        },
        {
            "x": -3,
            "y": 3,
            "z": -3,
            "elements": [
                "immersiveengineering:metal_decoration0@4"
            ]
        },
        {
            "x": 4,
            "y": 1,
            "z": 5,
            "elements": [
                "immersiveengineering:metal_decoration0@2"
            ]
        },
        {
            "x": -6,
            "y": -1,
            "z": -5,
            "elements": [
                "immersiveengineering:sheetmetal@8"
            ]
        },
        {
            "x": -4,
            "y": 3,
            "z": -3,
            "elements": [
                "immersiveengineering:sheetmetal@8"
            ]
        },
        {
            "x": -7,
            "y": -1,
            "z": -5,
            "elements": [
                "immersiveengineering:metal_decoration0@4"
            ]
        },
        {
            "x": -5,
            "y": 3,
            "z": -3,
            "elements": [
                "immersiveengineering:sheetmetal@8"
            ]
        },
        {
            "x": -6,
            "y": 3,
            "z": -3,
            "elements": [
                "immersiveengineering:sheetmetal@8"
            ]
        },
        {
            "x": -7,
            "y": 3,
            "z": -3,
            "elements": [
                "immersiveengineering:metal_decoration0@4"
            ]
        },
        {
            "x": 10,
            "y": 2,
            "z": -3,
            "elements": [
                "immersiveengineering:sheetmetal@8"
            ]
        },
        {
            "x": 9,
            "y": 2,
            "z": -3,
            "nbt": {"id":"immersiveengineering:ieslab","slabType":"1"},
            "elements": [
                "immersiveengineering:sheetmetal_slab@5"
            ]
        },
        {
            "x": 8,
            "y": 2,
            "z": -3,
            "elements": [
                "immersiveengineering:metal_device1@6"
            ]
        },
        {
            "x": 6,
            "y": 2,
            "z": -3,
            "elements": [
                "immersiveengineering:sheetmetal@8"
            ]
        },
        {
            "x": -1,
            "y": 2,
            "z": 5,
            "elements": [
                "immersiveengineering:metal_decoration0@2"
            ]
        },
        {
            "x": -3,
            "y": 2,
            "z": -3,
            "elements": [
                "immersiveengineering:sheetmetal@8"
            ]
        },
        {
            "x": 4,
            "y": 2,
            "z": 5,
            "elements": [
                "immersiveengineering:metal_decoration0@2"
            ]
        },
        {
            "x": -5,
            "y": 2,
            "z": -3,
            "elements": [
                "immersiveengineering:metal_device1@6"
            ]
        },
        {
            "x": -6,
            "y": 2,
            "z": -3,
            "nbt": {"id":"immersiveengineering:ieslab","slabType":"1"},
            "elements": [
                "immersiveengineering:sheetmetal_slab@5"
            ]
        },
        {
            "x": -7,
            "y": 2,
            "z": -3,
            "elements": [
                "immersiveengineering:sheetmetal@8"
            ]
        },
        {
            "x": 10,
            "y": 1,
            "z": -3,
            "elements": [
                "immersiveengineering:sheetmetal@0"
            ]
        },
        {
            "x": 9,
            "y": 1,
            "z": -3,
            "nbt": {"id":"immersiveengineering:ieslab","slabType":"0"},
            "elements": [
                "immersiveengineering:sheetmetal_slab@5"
            ]
        },
        {
            "x": 8,
            "y": 1,
            "z": -3,
            "nbt": {"conveyorBeltSubtypeNBT":{"dyeColour":"-1","direction":"0"},"conveyorBeltSubtype":"immersiveengineering:conveyor","id":"immersiveengineering:conveyorbelt"},
            "elements": [
                "immersiveengineering:conveyor@0"
            ]
        },
        {
            "x": 7,
            "y": 1,
            "z": -3,
            "nbt": {"conveyorBeltSubtypeNBT":{"dyeColour":"-1","direction":"0"},"conveyorBeltSubtype":"immersiveengineering:conveyor","id":"immersiveengineering:conveyorbelt"},
            "elements": [
                "immersiveengineering:conveyor@0"
            ]
        },
        {
            "x": 6,
            "y": 1,
            "z": -3,
            "elements": [
                "immersiveengineering:sheetmetal@8"
            ]
        },
        {
            "x": -4,
            "y": -1,
            "z": 3,
            "elements": [
                "immersiveengineering:metal_decoration0@4"
            ]
        },
        {
            "x": -3,
            "y": -1,
            "z": 3,
            "elements": [
                "immersiveengineering:sheetmetal@8"
            ]
        },
        {
            "x": -1,
            "y": 3,
            "z": 5,
            "elements": [
                "immersiveengineering:stone_decoration@8"
            ]
        },
        {
            "x": -2,
            "y": -1,
            "z": 3,
            "elements": [
                "immersiveengineering:sheetmetal@8"
            ]
        },
        {
            "x": 0,
            "y": 3,
            "z": 5,
            "elements": [
                "immersiveengineering:metal_decoration0@5"
            ]
        },
        {
            "x": -1,
            "y": -1,
            "z": 3,
            "elements": [
                "immersiveengineering:sheetmetal@8"
            ]
        },
        {
            "x": 1,
            "y": 3,
            "z": 5,
            "elements": [
                "immersiveengineering:metal_decoration0@5"
            ]
        },
        {
            "x": 0,
            "y": -1,
            "z": 3,
            "elements": [
                "immersiveengineering:sheetmetal@8"
            ]
        },
        {
            "x": 2,
            "y": 3,
            "z": 5,
            "elements": [
                "immersiveengineering:metal_decoration0@5"
            ]
        },
        {
            "x": 1,
            "y": -1,
            "z": 3,
            "elements": [
                "immersiveengineering:sheetmetal@8"
            ]
        },
        {
            "x": 3,
            "y": 3,
            "z": 5,
            "elements": [
                "immersiveengineering:metal_decoration0@5"
            ]
        },
        {
            "x": 2,
            "y": -1,
            "z": 3,
            "elements": [
                "immersiveengineering:sheetmetal@8"
            ]
        },
        {
            "x": -3,
            "y": 1,
            "z": -3,
            "elements": [
                "immersiveengineering:sheetmetal@8"
            ]
        },
        {
            "x": 4,
            "y": 3,
            "z": 5,
            "elements": [
                "immersiveengineering:stone_decoration@8"
            ]
        },
        {
            "x": 3,
            "y": -1,
            "z": 3,
            "elements": [
                "immersiveengineering:sheetmetal@8"
            ]
        },
        {
            "x": -4,
            "y": 1,
            "z": -3,
            "nbt": {"conveyorBeltSubtypeNBT":{"dyeColour":"-1","direction":"0"},"conveyorBeltSubtype":"immersiveengineering:conveyor","id":"immersiveengineering:conveyorbelt"},
            "elements": [
                "immersiveengineering:conveyor@0"
            ]
        },
        {
            "x": 4,
            "y": -1,
            "z": 3,
            "elements": [
                "immersiveengineering:sheetmetal@8"
            ]
        },
        {
            "x": -5,
            "y": 1,
            "z": -3,
            "nbt": {"conveyorBeltSubtypeNBT":{"dyeColour":"-1","direction":"0"},"conveyorBeltSubtype":"immersiveengineering:conveyor","id":"immersiveengineering:conveyorbelt"},
            "elements": [
                "immersiveengineering:conveyor@0"
            ]
        },
        {
            "x": 5,
            "y": -1,
            "z": 3,
            "elements": [
                "immersiveengineering:sheetmetal@8"
            ]
        },
        {
            "x": -6,
            "y": 1,
            "z": -3,
            "nbt": {"id":"immersiveengineering:ieslab","slabType":"0"},
            "elements": [
                "immersiveengineering:sheetmetal_slab@5"
            ]
        },
        {
            "x": 6,
            "y": -1,
            "z": 3,
            "elements": [
                "immersiveengineering:sheetmetal@8"
            ]
        },
        {
            "x": -7,
            "y": 1,
            "z": -3,
            "elements": [
                "immersiveengineering:sheetmetal@0"
            ]
        },
        {
            "x": 7,
            "y": -1,
            "z": 3,
            "elements": [
                "immersiveengineering:metal_decoration0@4"
            ]
        },
        {
            "x": 10,
            "y": 0,
            "z": -3,
            "elements": [
                "immersiveengineering:sheetmetal@8"
            ]
        },
        {
            "x": 9,
            "y": 0,
            "z": -3,
            "elements": [
                "stevescarts:blockmetalstorage@2"
            ]
        },
        {
            "x": 8,
            "y": 0,
            "z": -3,
            "elements": [
                "appliedenergistics2:fluix_block@0"
            ]
        },
        {
            "x": 7,
            "y": 0,
            "z": -3,
            "elements": [
                "stevescarts:blockmetalstorage@2"
            ]
        },
        {
            "x": 9,
            "y": 4,
            "z": -1,
            "elements": [
                "immersiveengineering:metal_device1@6"
            ]
        },
        {
            "x": 6,
            "y": 0,
            "z": -3,
            "elements": [
                "immersiveengineering:sheetmetal@8"
            ]
        },
        {
            "x": 8,
            "y": 4,
            "z": -1,
            "elements": [
                "immersiveengineering:metal_device1@6"
            ]
        },
        {
            "x": 7,
            "y": 4,
            "z": -1,
            "nbt": {"id":"immersiveengineering:ieslab","slabType":"0"},
            "elements": [
                "immersiveengineering:sheetmetal_slab@8"
            ]
        },
        {
            "x": 6,
            "y": 4,
            "z": -1,
            "nbt": {"id":"immersiveengineering:ieslab","slabType":"0"},
            "elements": [
                "immersiveengineering:sheetmetal_slab@8"
            ]
        },
        {
            "x": -4,
            "y": 0,
            "z": 3,
            "elements": [
                "immersiveengineering:sheetmetal@8"
            ]
        },
        {
            "x": -3,
            "y": 0,
            "z": 3,
            "elements": [
                "stevescarts:blockmetalstorage@2"
            ]
        },
        {
            "x": -2,
            "y": 0,
            "z": 3,
            "elements": [
                "stevescarts:blockmetalstorage@2"
            ]
        },
        {
            "x": -1,
            "y": 0,
            "z": 3,
            "elements": [
                "stevescarts:blockmetalstorage@2"
            ]
        },
        {
            "x": 0,
            "y": 0,
            "z": 3,
            "elements": [
                "stevescarts:blockmetalstorage@2"
            ]
        },
        {
            "x": 1,
            "y": 0,
            "z": 3,
            "elements": [
                "stevescarts:blockmetalstorage@2"
            ]
        },
        {
            "x": -3,
            "y": 0,
            "z": -3,
            "elements": [
                "immersiveengineering:sheetmetal@8"
            ]
        },
        {
            "x": 2,
            "y": 0,
            "z": 3,
            "elements": [
                "stevescarts:blockmetalstorage@2"
            ]
        },
        {
            "x": -4,
            "y": 0,
            "z": -3,
            "elements": [
                "stevescarts:blockmetalstorage@2"
            ]
        },
        {
            "x": 3,
            "y": 0,
            "z": 3,
            "elements": [
                "stevescarts:blockmetalstorage@2"
            ]
        },
        {
            "x": -5,
            "y": 0,
            "z": -3,
            "elements": [
                "appliedenergistics2:fluix_block@0"
            ]
        },
        {
            "x": 4,
            "y": 0,
            "z": 3,
            "elements": [
                "stevescarts:blockmetalstorage@2"
            ]
        },
        {
            "x": -3,
            "y": 4,
            "z": -1,
            "nbt": {"id":"immersiveengineering:ieslab","slabType":"0"},
            "elements": [
                "immersiveengineering:sheetmetal_slab@8"
            ]
        },
        {
            "x": -6,
            "y": 0,
            "z": -3,
            "elements": [
                "stevescarts:blockmetalstorage@2"
            ]
        },
        {
            "x": 5,
            "y": 0,
            "z": 3,
            "elements": [
                "stevescarts:blockmetalstorage@2"
            ]
        },
        {
            "x": -4,
            "y": 4,
            "z": -1,
            "nbt": {"id":"immersiveengineering:ieslab","slabType":"0"},
            "elements": [
                "immersiveengineering:sheetmetal_slab@8"
            ]
        },
        {
            "x": -7,
            "y": 0,
            "z": -3,
            "elements": [
                "immersiveengineering:sheetmetal@8"
            ]
        },
        {
            "x": 6,
            "y": 0,
            "z": 3,
            "elements": [
                "stevescarts:blockmetalstorage@2"
            ]
        },
        {
            "x": -5,
            "y": 4,
            "z": -1,
            "elements": [
                "immersiveengineering:metal_device1@6"
            ]
        },
        {
            "x": 7,
            "y": 0,
            "z": 3,
            "elements": [
                "immersiveengineering:sheetmetal@8"
            ]
        },
        {
            "x": -6,
            "y": 4,
            "z": -1,
            "elements": [
                "immersiveengineering:metal_device1@6"
            ]
        },
        {
            "x": 10,
            "y": -1,
            "z": -3,
            "elements": [
                "immersiveengineering:metal_decoration0@4"
            ]
        },
        {
            "x": 9,
            "y": -1,
            "z": -3,
            "elements": [
                "immersiveengineering:sheetmetal@8"
            ]
        },
        {
            "x": 8,
            "y": -1,
            "z": -3,
            "elements": [
                "immersiveengineering:sheetmetal@8"
            ]
        },
        {
            "x": 10,
            "y": 3,
            "z": -1,
            "elements": [
                "immersiveengineering:metal_decoration0@4"
            ]
        },
        {
            "x": 7,
            "y": -1,
            "z": -3,
            "elements": [
                "immersiveengineering:sheetmetal@8"
            ]
        },
        {
            "x": 9,
            "y": 3,
            "z": -1,
            "elements": [
                "immersiveengineering:sheetmetal@8"
            ]
        },
        {
            "x": 6,
            "y": -1,
            "z": -3,
            "elements": [
                "immersiveengineering:metal_decoration0@4"
            ]
        },
        {
            "x": 8,
            "y": 3,
            "z": -1,
            "elements": [
                "immersiveengineering:sheetmetal@8"
            ]
        },
        {
            "x": 7,
            "y": 3,
            "z": -1,
            "elements": [
                "immersiveengineering:sheetmetal@8"
            ]
        },
        {
            "x": 6,
            "y": 3,
            "z": -1,
            "elements": [
                "immersiveengineering:sheetmetal@8"
            ]
        },
        {
            "x": -4,
            "y": 1,
            "z": 3,
            "elements": [
                "immersiveengineering:sheetmetal@0"
            ]
        },
        {
            "x": 5,
            "y": 3,
            "z": -1,
            "elements": [
                "immersiveengineering:metal_decoration0@4"
            ]
        },
        {
            "x": 4,
            "y": 3,
            "z": -1,
            "elements": [
                "immersiveengineering:storage@8"
            ]
        },
        {
            "x": -2,
            "y": 1,
            "z": 3,
            "nbt": {"id":"immersiveengineering:ieslab","slabType":"0"},
            "elements": [
                "immersiveengineering:sheetmetal_slab@5"
            ]
        },
        {
            "x": 3,
            "y": 3,
            "z": -1,
            "elements": [
                "immersiveengineering:metal_decoration0@5"
            ]
        },
        {
            "x": -1,
            "y": 1,
            "z": 3,
            "nbt": {"id":"immersiveengineering:ieslab","slabType":"0"},
            "elements": [
                "immersiveengineering:sheetmetal_slab@5"
            ]
        },
        {
            "x": 2,
            "y": 3,
            "z": -1,
            "elements": [
                "immersiveengineering:metal_decoration0@5"
            ]
        },
        {
            "x": 0,
            "y": 1,
            "z": 3,
            "nbt": {"id":"immersiveengineering:ieslab","slabType":"0"},
            "elements": [
                "immersiveengineering:sheetmetal_slab@5"
            ]
        },
        {
            "x": 1,
            "y": 3,
            "z": -1,
            "elements": [
                "immersiveengineering:metal_decoration0@5"
            ]
        },
        {
            "x": 1,
            "y": 1,
            "z": 3,
            "nbt": {"id":"immersiveengineering:ieslab","slabType":"0"},
            "elements": [
                "immersiveengineering:sheetmetal_slab@5"
            ]
        },
        {
            "x": 0,
            "y": 3,
            "z": -1,
            "elements": [
                "immersiveengineering:metal_decoration0@5"
            ]
        },
        {
            "x": -3,
            "y": -1,
            "z": -3,
            "elements": [
                "immersiveengineering:metal_decoration0@4"
            ]
        },
        {
            "x": 2,
            "y": 1,
            "z": 3,
            "nbt": {"id":"immersiveengineering:ieslab","slabType":"0"},
            "elements": [
                "immersiveengineering:sheetmetal_slab@5"
            ]
        },
        {
            "x": -1,
            "y": 3,
            "z": -1,
            "elements": [
                "immersiveengineering:storage@8"
            ]
        },
        {
            "x": -4,
            "y": -1,
            "z": -3,
            "elements": [
                "immersiveengineering:sheetmetal@8"
            ]
        },
        {
            "x": -3,
            "y": 1,
            "z": 3,
            "nbt": {"id":"immersiveengineering:ieslab","slabType":"0"},
            "elements": [
                "immersiveengineering:sheetmetal_slab@5"
            ]
        },
        {
            "x": -2,
            "y": 3,
            "z": -1,
            "elements": [
                "immersiveengineering:metal_decoration0@4"
            ]
        },
        {
            "x": -5,
            "y": -1,
            "z": -3,
            "elements": [
                "immersiveengineering:sheetmetal@8"
            ]
        },
        {
            "x": 4,
            "y": 1,
            "z": 3,
            "nbt": {"id":"immersiveengineering:ieslab","slabType":"0"},
            "elements": [
                "immersiveengineering:sheetmetal_slab@5"
            ]
        },
        {
            "x": -3,
            "y": 3,
            "z": -1,
            "elements": [
                "immersiveengineering:sheetmetal@8"
            ]
        },
        {
            "x": -6,
            "y": -1,
            "z": -3,
            "elements": [
                "immersiveengineering:sheetmetal@8"
            ]
        },
        {
            "x": 5,
            "y": 1,
            "z": 3,
            "nbt": {"id":"immersiveengineering:ieslab","slabType":"0"},
            "elements": [
                "immersiveengineering:sheetmetal_slab@5"
            ]
        },
        {
            "x": -4,
            "y": 3,
            "z": -1,
            "elements": [
                "immersiveengineering:sheetmetal@8"
            ]
        },
        {
            "x": -7,
            "y": -1,
            "z": -3,
            "elements": [
                "immersiveengineering:metal_decoration0@4"
            ]
        },
        {
            "x": 6,
            "y": 1,
            "z": 3,
            "nbt": {"id":"immersiveengineering:ieslab","slabType":"0"},
            "elements": [
                "immersiveengineering:sheetmetal_slab@5"
            ]
        },
        {
            "x": -5,
            "y": 3,
            "z": -1,
            "elements": [
                "immersiveengineering:sheetmetal@8"
            ]
        },
        {
            "x": -6,
            "y": 3,
            "z": -1,
            "elements": [
                "immersiveengineering:sheetmetal@8"
            ]
        },
        {
            "x": 7,
            "y": 1,
            "z": 3,
            "elements": [
                "immersiveengineering:sheetmetal@0"
            ]
        },
        {
            "x": -7,
            "y": 3,
            "z": -1,
            "elements": [
                "immersiveengineering:metal_decoration0@4"
            ]
        },
        {
            "x": 10,
            "y": 2,
            "z": -1,
            "elements": [
                "immersiveengineering:sheetmetal@8"
            ]
        },
        {
            "x": 9,
            "y": 2,
            "z": -1,
            "nbt": {"id":"immersiveengineering:ieslab","slabType":"1"},
            "elements": [
                "immersiveengineering:sheetmetal_slab@5"
            ]
        },
        {
            "x": 8,
            "y": 2,
            "z": -1,
            "elements": [
                "immersiveengineering:metal_device1@6"
            ]
        },
        {
            "x": 7,
            "y": 2,
            "z": -1,
            "elements": [
                "immersiveengineering:metal_device1@6"
            ]
        },
        {
            "x": -4,
            "y": 2,
            "z": 3,
            "elements": [
                "immersiveengineering:sheetmetal@8"
            ]
        },
        {
            "x": 5,
            "y": 2,
            "z": -1,
            "elements": [
                "immersiveengineering:metal_decoration0@4"
            ]
        },
        {
            "x": -3,
            "y": 2,
            "z": 3,
            "nbt": {"id":"immersiveengineering:ieslab","slabType":"1"},
            "elements": [
                "immersiveengineering:sheetmetal_slab@5"
            ]
        },
        {
            "x": 4,
            "y": 2,
            "z": -1,
            "elements": [
                "immersiveengineering:metal_decoration0@5"
            ]
        },
        {
            "x": -2,
            "y": 2,
            "z": 3,
            "nbt": {"id":"immersiveengineering:ieslab","slabType":"1"},
            "elements": [
                "immersiveengineering:sheetmetal_slab@5"
            ]
        },
        {
            "x": -1,
            "y": 2,
            "z": 3,
            "nbt": {"id":"immersiveengineering:ieslab","slabType":"1"},
            "elements": [
                "immersiveengineering:sheetmetal_slab@5"
            ]
        },
        {
            "x": 0,
            "y": 2,
            "z": 3,
            "nbt": {"id":"immersiveengineering:ieslab","slabType":"1"},
            "elements": [
                "immersiveengineering:sheetmetal_slab@5"
            ]
        },
        {
            "x": 1,
            "y": 2,
            "z": 3,
            "nbt": {"id":"immersiveengineering:ieslab","slabType":"1"},
            "elements": [
                "immersiveengineering:sheetmetal_slab@5"
            ]
        },
        {
            "x": 2,
            "y": 2,
            "z": 3,
            "nbt": {"id":"immersiveengineering:ieslab","slabType":"1"},
            "elements": [
                "immersiveengineering:sheetmetal_slab@5"
            ]
        },
        {
            "x": -1,
            "y": 2,
            "z": -1,
            "elements": [
                "immersiveengineering:metal_decoration0@5"
            ]
        },
        {
            "x": 3,
            "y": 2,
            "z": 3,
            "nbt": {"id":"immersiveengineering:ieslab","slabType":"1"},
            "elements": [
                "immersiveengineering:sheetmetal_slab@5"
            ]
        },
        {
            "x": -2,
            "y": 2,
            "z": -1,
            "elements": [
                "immersiveengineering:metal_decoration0@4"
            ]
        },
        {
            "x": 4,
            "y": 2,
            "z": 3,
            "nbt": {"id":"immersiveengineering:ieslab","slabType":"1"},
            "elements": [
                "immersiveengineering:sheetmetal_slab@5"
            ]
        },
        {
            "x": 5,
            "y": 2,
            "z": 3,
            "nbt": {"id":"immersiveengineering:ieslab","slabType":"1"},
            "elements": [
                "immersiveengineering:sheetmetal_slab@5"
            ]
        },
        {
            "x": -4,
            "y": 2,
            "z": -1,
            "elements": [
                "immersiveengineering:metal_device1@6"
            ]
        },
        {
            "x": 6,
            "y": 2,
            "z": 3,
            "nbt": {"id":"immersiveengineering:ieslab","slabType":"1"},
            "elements": [
                "immersiveengineering:sheetmetal_slab@5"
            ]
        },
        {
            "x": -5,
            "y": 2,
            "z": -1,
            "elements": [
                "immersiveengineering:metal_device1@6"
            ]
        },
        {
            "x": -6,
            "y": 2,
            "z": -1,
            "nbt": {"id":"immersiveengineering:ieslab","slabType":"1"},
            "elements": [
                "immersiveengineering:sheetmetal_slab@5"
            ]
        },
        {
            "x": 7,
            "y": 2,
            "z": 3,
            "elements": [
                "immersiveengineering:sheetmetal@8"
            ]
        },
        {
            "x": -7,
            "y": 2,
            "z": -1,
            "elements": [
                "immersiveengineering:sheetmetal@8"
            ]
        },
        {
            "x": 10,
            "y": 1,
            "z": -1,
            "elements": [
                "immersiveengineering:sheetmetal@0"
            ]
        },
        {
            "x": 9,
            "y": 1,
            "z": -1,
            "nbt": {"id":"immersiveengineering:ieslab","slabType":"0"},
            "elements": [
                "immersiveengineering:sheetmetal_slab@5"
            ]
        },
        {
            "x": 8,
            "y": 1,
            "z": -1,
            "nbt": {"conveyorBeltSubtypeNBT":{"dyeColour":"-1","direction":"0"},"conveyorBeltSubtype":"immersiveengineering:conveyor","id":"immersiveengineering:conveyorbelt"},
            "elements": [
                "immersiveengineering:conveyor@0"
            ]
        },
        {
            "x": 7,
            "y": 1,
            "z": -1,
            "nbt": {"conveyorBeltSubtypeNBT":{"dyeColour":"-1","direction":"0"},"conveyorBeltSubtype":"immersiveengineering:conveyor","id":"immersiveengineering:conveyorbelt"},
            "elements": [
                "immersiveengineering:conveyor@0"
            ]
        },
        {
            "x": 6,
            "y": 1,
            "z": -1,
            "nbt": {"conveyorBeltSubtypeNBT":{"dyeColour":"-1","direction":"0"},"conveyorBeltSubtype":"immersiveengineering:conveyor","id":"immersiveengineering:conveyorbelt"},
            "elements": [
                "immersiveengineering:conveyor@0"
            ]
        },
        {
            "x": -6,
            "y": -1,
            "z": 1,
            "elements": [
                "immersiveengineering:metal_decoration0@4"
            ]
        },
        {
            "x": 5,
            "y": 1,
            "z": -1,
            "elements": [
                "immersiveengineering:metal_decoration0@4"
            ]
        },
        {
            "x": -4,
            "y": 3,
            "z": 3,
            "elements": [
                "immersiveengineering:metal_decoration0@4"
            ]
        },
        {
            "x": -5,
            "y": -1,
            "z": 1,
            "elements": [
                "immersiveengineering:sheetmetal@8"
            ]
        },
        {
            "x": -3,
            "y": 3,
            "z": 3,
            "elements": [
                "immersiveengineering:sheetmetal@8"
            ]
        },
        {
            "x": 4,
            "y": 1,
            "z": -1,
            "elements": [
                "immersiveengineering:metal_decoration0@5"
            ]
        },
        {
            "x": -4,
            "y": -1,
            "z": 1,
            "elements": [
                "immersiveengineering:sheetmetal@8"
            ]
        },
        {
            "x": -2,
            "y": 3,
            "z": 3,
            "elements": [
                "immersiveengineering:sheetmetal@8"
            ]
        },
        {
            "x": -3,
            "y": -1,
            "z": 1,
            "elements": [
                "immersiveengineering:sheetmetal@8"
            ]
        },
        {
            "x": -1,
            "y": 3,
            "z": 3,
            "elements": [
                "immersiveengineering:sheetmetal@8"
            ]
        },
        {
            "x": -2,
            "y": -1,
            "z": 1,
            "elements": [
                "immersiveengineering:sheetmetal@8"
            ]
        },
        {
            "x": 0,
            "y": 3,
            "z": 3,
            "elements": [
                "immersiveengineering:sheetmetal@8"
            ]
        },
        {
            "x": -1,
            "y": -1,
            "z": 1,
            "elements": [
                "immersiveengineering:sheetmetal@8"
            ]
        },
        {
            "x": 1,
            "y": 3,
            "z": 3,
            "elements": [
                "immersiveengineering:sheetmetal@8"
            ]
        },
        {
            "x": 0,
            "y": -1,
            "z": 1,
            "elements": [
                "immersiveengineering:sheetmetal@8"
            ]
        },
        {
            "x": 2,
            "y": 3,
            "z": 3,
            "elements": [
                "immersiveengineering:sheetmetal@8"
            ]
        },
        {
            "x": -1,
            "y": 1,
            "z": -1,
            "elements": [
                "immersiveengineering:metal_decoration0@5"
            ]
        },
        {
            "x": 1,
            "y": -1,
            "z": 1,
            "elements": [
                "immersiveengineering:sheetmetal@8"
            ]
        },
        {
            "x": -2,
            "y": 1,
            "z": -1,
            "elements": [
                "immersiveengineering:metal_decoration0@4"
            ]
        },
        {
            "x": 3,
            "y": 3,
            "z": 3,
            "elements": [
                "immersiveengineering:sheetmetal@8"
            ]
        },
        {
            "x": 2,
            "y": -1,
